Workbook

Sheet base_regsub
A1: CHAVE | B1: ANO_EMPENHO | C1: ANO_LIQUIDAÇÃO | D1: CÓDIGO_PROJ_ATIV | E1: DESCRIÇÃO_PROJ_ATIV | F1: SUBPREFEITURA | G1: valor
A2: =_xlfn.CONCAT(B2, ".", D2) -> 2022.1003 | B2: 2022 | C2: 2022 | D2: 1003 | E2: Ampliação, Reforma e Requalificação de Edificação do Tribunal de Contas do Município | F2: Subprefeitura Vila Mariana | G2: 94500
A3: =_xlfn.CONCAT(B3, ".", D3) -> 2022.1032 | B3: 2022 | C3: 2022 | D3: 1032 | E3: Construção da Fábrica do Samba | F3: Subprefeitura Lapa | G3: 7738081.3
A4: =_xlfn.CONCAT(B4, ".", D4) -> 2022.1055 | B4: 2022 | C4: 2023 | D4: 1055 | E4: Ampliação, Reforma e Requalificação das Instalações para a Guarda Civil Metropolitana | F4: Subprefeitura Casa Verde/Cachoeirinha | G4: 834021.38
A5: =_xlfn.CONCAT(B5, ".", D5) -> 2022.1055 | B5: 2022 | C5: 2023 | D5: 1055 | E5: Ampliação, Reforma e Requalificação das Instalações para a Guarda Civil Metropolitana | F5: Subprefeitura Cidade Tiradentes | G5: 59405.25
A6: =_xlfn.CONCAT(B6, ".", D6) -> 2022.1055 | B6: 2022 | C6: 2023 | D6: 1055 | E6: Ampliação, Reforma e Requalificação das Instalações para a Guarda Civil Metropolitana | F6: Subprefeitura Pirituba/Jaraguá | G6: 12452.76
A7: =_xlfn.CONCAT(B7, ".", D7) -> 2022.1055 | B7: 2022 | C7: 2023 | D7: 1055 | E7: Ampliação, Reforma e Requalificação das Instalações para a Guarda Civil Metropolitana | F7: Subprefeitura Santana/Tucuruvi | G7: 299600
A8: =_xlfn.CONCAT(B8, ".", D8) -> 2022.1055 | B8: 2022 | C8: 2023 | D8: 1055 | E8: Ampliação, Reforma e Requalificação das Instalações para a Guarda Civil Metropolitana | F8: Subprefeitura São Miguel Paulista | G8: 132998.5
A9: =_xlfn.CONCAT(B9, ".", D9) -> 2022.1055 | B9: 2022 | C9: 2023 | D9: 1055 | E9: Ampliação, Reforma e Requalificação das Instalações para a Guarda Civil Metropolitana | F9: Subprefeitura Vila Mariana | G9: 81457.93
A10: =_xlfn.CONCAT(B10, ".", D10) -> 2022.1095 | B10: 2022 | C10: 2022 | D10: 1095 | E10: Construção de Terminais de Ônibus | F10: Subprefeitura São Mateus | G10: 40432.25
A11: =_xlfn.CONCAT(B11, ".", D11) -> 2022.1095 | B11: 2022 | C11: 2023 | D11: 1095 | E11: Construção de Terminais de Ônibus | F11: Subprefeitura São Mateus | G11: 193469.11
A12: =_xlfn.CONCAT(B12, ".", D12) -> 2022.1096 | B12: 2022 | C12: 2022 | D12: 1096 | E12: Acessibilidade, Ampliação, Reforma e Requalificação de Terminais de Ônibus | F12: Subprefeitura Aricanduva/Formosa/Carrão | G12: 160837.31
A13: =_xlfn.CONCAT(B13, ".", D13) -> 2022.1096 | B13: 2022 | C13: 2022 | D13: 1096 | E13: Acessibilidade, Ampliação, Reforma e Requalificação de Terminais de Ônibus | F13: Subprefeitura Campo Limpo | G13: 232482.36
... A24463: =_xlfn.CONCAT(B24463, ".", D24463) -> 2025.7208 | B24463: 2025 | C24463: 2025 | D24463: 7208 | E24463: Parceria Público-Privada (PPP) - CEU | F24463: Subprefeitura M'Boi Mirim | G24463: 33600000

Sheet resumo_totais
A1: Exercício | B1: Despesa Liquidada | C1: Despesa Regionalizada por subprefeitura | D1: % Regionalizado por subprefeitura | E1: Despesa Regionalizada Cesta IDRGP | F1: % Regionalizado Cesta IDRGP
A2: 2022 | B2: 8.7446431e+10 | C2: 1.5957088e+10 | D2: 0.27504656 | E2: =SUMIFS(cesta_idrgp!E:E, cesta_idrgp!B:B, resumo_totais!A2) -> 2.2673822e+09 | F2: =E2/B2 -> 0.025928814
A3: 2023 | B3: 1.0438074e+11 | C3: 3.2845352e+10 | D3: 0.32367165 | E3: =SUMIFS(cesta_idrgp!E:E, cesta_idrgp!B:B, resumo_totais!A3) -> 4.8495615e+09 | F3: =E3/B3 -> 0.04646031
A4: 2024 | B4: 1.2213711e+11 | C4: 3.9601842e+10 | D4: 0.37302502 | E4: =SUMIFS(cesta_idrgp!E:E, cesta_idrgp!B:B, resumo_totais!A4) -> 6.036653e+09 | F4: =E4/B4 -> 0.049425218
A5: 2025 | B5: 1.2170326e+11 | C5: 5.7155703e+10 | D5: 0.47094266 | E5: =SUMIFS(cesta_idrgp!E:E, cesta_idrgp!B:B, resumo_totais!A5) -> 5.5658347e+09 | F5: =E5/B5 -> 0.045732834
A6: Total | B6: =SUM(B2:B5) -> 4.3566753e+11 | C6: =SUM(C2:C5) -> 1.4555998e+11 | D6: 0.36888766 | E6: =SUM(E2:E5) -> 1.8719431e+10 | F6: =E6/B6 -> 0.04296724

Sheet cesta_idrgp
A1: chave | B1: ano | C1: código_proj_ativ | D1: descrição_proj_ativ | E1: regionalizado_sub
A2: =_xlfn.CONCAT(B2, ".", C2) -> 2024.1170 | B2: 2024 | C2: 1170 | D2: Intervenção, Urbanização e Melhoria de Bairros - Plano de Obras das Subprefeituras | E2: =SUMIFS(base_regsub!G:G, base_regsub!A:A, cesta_idrgp!$A2, base_regsub!D:D, cesta_idrgp!$C2) -> 8.1957058e+08
A3: =_xlfn.CONCAT(B3, ".", C3) -> 2024.1193 | B3: 2024 | C3: 1193 | D3: Obras e Serviços nas Áreas de Riscos Geológicos - Preventivas | E3: =SUMIFS(base_regsub!G:G, base_regsub!A:A, cesta_idrgp!$A3, base_regsub!D:D, cesta_idrgp!$C3) -> 27222208
A4: =_xlfn.CONCAT(B4, ".", C4) -> 2024.1194 | B4: 2024 | C4: 1194 | D4: Obras e Serviços nas Áreas de Riscos Geológicos - Emergenciais | E4: =SUMIFS(base_regsub!G:G, base_regsub!A:A, cesta_idrgp!$A4, base_regsub!D:D, cesta_idrgp!$C4) -> 0
A5: =_xlfn.CONCAT(B5, ".", C5) -> 2024.1276 | B5: 2024 | C5: 1276 | D5: Projetos e Ações de Apoio Habitacional | E5: =SUMIFS(base_regsub!G:G, base_regsub!A:A, cesta_idrgp!$A5, base_regsub!D:D, cesta_idrgp!$C5) -> 68876142
A6: =_xlfn.CONCAT(B6, ".", C6) -> 2024.1525 | B6: 2024 | C6: 1525 | D6: Construção e Implantação de Equipamentos de Atenção Básica e Especialidades | E6: =SUMIFS(base_regsub!G:G, base_regsub!A:A, cesta_idrgp!$A6, base_regsub!D:D, cesta_idrgp!$C6) -> 90495496
A7: =_xlfn.CONCAT(B7, ".", C7) -> 2024.1526 | B7: 2024 | C7: 1526 | D7: Ampliação, Reforma e Requalificação de Equipamentos de Atenção Básica e Especialidades | E7: =SUMIFS(base_regsub!G:G, base_regsub!A:A, cesta_idrgp!$A7, base_regsub!D:D, cesta_idrgp!$C7) -> 1.6252697e+08
A8: =_xlfn.CONCAT(B8, ".", C8) -> 2024.1530 | B8: 2024 | C8: 1530 | D8: Construção e Implantação de Equipamentos de Saúde Animal | E8: =SUMIFS(base_regsub!G:G, base_regsub!A:A, cesta_idrgp!$A8, base_regsub!D:D, cesta_idrgp!$C8) -> 1159882.2
A9: =_xlfn.CONCAT(B9, ".", C9) -> 2024.1535 | B9: 2024 | C9: 1535 | D9: Construção e Implantação de Equipamentos em Atenção Hospitalar e de Urgência e Emergência | E9: =SUMIFS(base_regsub!G:G, base_regsub!A:A, cesta_idrgp!$A9, base_regsub!D:D, cesta_idrgp!$C9) -> 31824615
A10: =_xlfn.CONCAT(B10, ".", C10) -> 2024.1536 | B10: 2024 | C10: 1536 | D10: Ampliação, Reforma e Requalificação de Equipamentos em Atenção Hospitalar e de Urgência e Emergência | E10: =SUMIFS(base_regsub!G:G, base_regsub!A:A, cesta_idrgp!$A10, base_regsub!D:D, cesta_idrgp!$C10) -> 2.113933e+08
A11: =_xlfn.CONCAT(B11, ".", C11) -> 2024.1702 | B11: 2024 | C11: 1702 | D11: Construção e Implantação de Parques Urbanos e Lineares | E11: =SUMIFS(base_regsub!G:G, base_regsub!A:A, cesta_idrgp!$A11, base_regsub!D:D, cesta_idrgp!$C11) -> 2.6731174e+08
A12: =_xlfn.CONCAT(B12, ".", C12) -> 2024.1703 | B12: 2024 | C12: 1703 | D12: Ampliação, Reforma e Requalificação de Parques Urbanos e Lineares | E12: =SUMIFS(base_regsub!G:G, base_regsub!A:A, cesta_idrgp!$A12, base_regsub!D:D, cesta_idrgp!$C12) -> 69146654
A13: =_xlfn.CONCAT(B13, ".", C13) -> 2024.1895 | B13: 2024 | C13: 1895 | D13: Implantação de Equipamentos Esportivos | E13: =SUMIFS(base_regsub!G:G, base_regsub!A:A, cesta_idrgp!$A13, base_regsub!D:D, cesta_idrgp!$C13) -> 0
... A88: =_xlfn.CONCAT(B88, ".", C88) -> 2024.9007 | B88: 2024 | C88: 9007 | D88: UPA Sapopemba | E88: =SUMIFS(base_regsub!G:G, base_regsub!A:A, cesta_idrgp!$A88, base_regsub!D:D, cesta_idrgp!$C88) -> 0
A89: =_xlfn.CONCAT(B89, ".", C89) -> 2022.1170 | B89: 2022 | C89: 1170 | D89: =VLOOKUP(A89, base_regsub!A:E, 5, FALSE) -> Intervenção, Urbanização e Melhoria de Bairros - Plano de Obras das Subprefeituras | E89: =SUMIFS(base_regsub!G:G, base_regsub!A:A, cesta_idrgp!$A89, base_regsub!D:D, cesta_idrgp!$C89) -> 6.233351e+08
A90: =_xlfn.CONCAT(B90, ".", C90) -> 2022.1193 | B90: 2022 | C90: 1193 | D90: =VLOOKUP(A90, base_regsub!A:E, 5, FALSE) -> Obras e Serviços nas Áreas de Riscos Geológicos | E90: =SUMIFS(base_regsub!G:G, base_regsub!A:A, cesta_idrgp!$A90, base_regsub!D:D, cesta_idrgp!$C90) -> 1.356775e+08
A91: =_xlfn.CONCAT(B91, ".", C91) -> 2022.1194 | B91: 2022 | C91: 1194 | D91: =VLOOKUP(A91, base_regsub!A:E, 5, FALSE) -> #N/A | E91: =SUMIFS(base_regsub!G:G, base_regsub!A:A, cesta_idrgp!$A91, base_regsub!D:D, cesta_idrgp!$C91) -> 0
A92: =_xlfn.CONCAT(B92, ".", C92) -> 2022.1276 | B92: 2022 | C92: 1276 | D92: =VLOOKUP(A92, base_regsub!A:E, 5, FALSE) -> #N/A | E92: =SUMIFS(base_regsub!G:G, base_regsub!A:A, cesta_idrgp!$A92, base_regsub!D:D, cesta_idrgp!$C92) -> 0
A93: =_xlfn.CONCAT(B93, ".", C93) -> 2022.1525 | B93: 2022 | C93: 1525 | D93: =VLOOKUP(A93, base_regsub!A:E, 5, FALSE) -> #N/A | E93: =SUMIFS(base_regsub!G:G, base_regsub!A:A, cesta_idrgp!$A93, base_regsub!D:D, cesta_idrgp!$C93) -> 0
A94: =_xlfn.CONCAT(B94, ".", C94) -> 2022.1526 | B94: 2022 | C94: 1526 | D94: =VLOOKUP(A94, base_regsub!A:E, 5, FALSE) -> #N/A | E94: =SUMIFS(base_regsub!G:G, base_regsub!A:A, cesta_idrgp!$A94, base_regsub!D:D, cesta_idrgp!$C94) -> 0
A95: =_xlfn.CONCAT(B95, ".", C95) -> 2022.1530 | B95: 2022 | C95: 1530 | D95: =VLOOKUP(A95, base_regsub!A:E, 5, FALSE) -> #N/A | E95: =SUMIFS(base_regsub!G:G, base_regsub!A:A, cesta_idrgp!$A95, base_regsub!D:D, cesta_idrgp!$C95) -> 0
A96: =_xlfn.CONCAT(B96, ".", C96) -> 2022.1535 | B96: 2022 | C96: 1535 | D96: =VLOOKUP(A96, base_regsub!A:E, 5, FALSE) -> #N/A | E96: =SUMIFS(base_regsub!G:G, base_regsub!A:A, cesta_idrgp!$A96, base_regsub!D:D, cesta_idrgp!$C96) -> 0
A97: =_xlfn.CONCAT(B97, ".", C97) -> 2022.1536 | B97: 2022 | C97: 1536 | D97: =VLOOKUP(A97, base_regsub!A:E, 5, FALSE) -> Ampliação, Reforma e Requalificação de Equipamentos em Atenção Hospitalar e de Urgência e Emergência | E97: =SUMIFS(base_regsub!G:G, base_regsub!A:A, cesta_idrgp!$A97, base_regsub!D:D, cesta_idrgp!$C97) -> 36045.4
A98: =_xlfn.CONCAT(B98, ".", C98) -> 2022.1702 | B98: 2022 | C98: 1702 | D98: =VLOOKUP(A98, base_regsub!A:E, 5, FALSE) -> Construção e Implantação de Parques Urbanos e Lineares | E98: =SUMIFS(base_regsub!G:G, base_regsub!A:A, cesta_idrgp!$A98, base_regsub!D:D, cesta_idrgp!$C98) -> 25837166
A99: =_xlfn.CONCAT(B99, ".", C99) -> 2022.1703 | B99: 2022 | C99: 1703 | D99: =VLOOKUP(A99, base_regsub!A:E, 5, FALSE) -> Ampliação, Reforma e Requalificação de Parques Urbanos e Lineares | E99: =SUMIFS(base_regsub!G:G, base_regsub!A:A, cesta_idrgp!$A99, base_regsub!D:D, cesta_idrgp!$C99) -> 11059459
A100: =_xlfn.CONCAT(B100, ".", C100) -> 2022.1895 | B100: 2022 | C100: 1895 | D100: =VLOOKUP(A100, base_regsub!A:E, 5, FALSE) -> #N/A | E100: =SUMIFS(base_regsub!G:G, base_regsub!A:A, cesta_idrgp!$A100, base_regsub!D:D, cesta_idrgp!$C100) -> 0
... A153: =_xlfn.CONCAT(B153, ".", C153) -> 2022.5400 | B153: 2022 | C153: 5400 | D153: =VLOOKUP(A153, base_regsub!A:E, 5, FALSE) -> #N/A | E153: =SUMIFS(base_regsub!G:G, base_regsub!A:A, cesta_idrgp!$A153, base_regsub!D:D, cesta_idrgp!$C153) -> 0
A154: =_xlfn.CONCAT(B154, ".", C154) -> 2022.5406 | B154: 2022 | C154: 5406 | D154: =VLOOKUP(A154, base_regsub!A:E, 5, FALSE) -> Ampliação, Reforma e Requalificação de Equipamentos Culturais | E154: =SUMIFS(base_regsub!G:G, base_regsub!A:A, cesta_idrgp!$A154, base_regsub!D:D, cesta_idrgp!$C154) -> 630583.35
A155: =_xlfn.CONCAT(B155, ".", C155) -> 2022.5407 | B155: 2022 | C155: 5407 | D155: =VLOOKUP(A155, base_regsub!A:E, 5, FALSE) -> #N/A | E155: =SUMIFS(base_regsub!G:G, base_regsub!A:A, cesta_idrgp!$A155, base_regsub!D:D, cesta_idrgp!$C155) -> 0
A156: =_xlfn.CONCAT(B156, ".", C156) -> 2022.5425 | B156: 2022 | C156: 5425 | D156: =VLOOKUP(A156, base_regsub!A:E, 5, FALSE) -> Implantação da Casa de Cultura Cidade Ademar | E156: =SUMIFS(base_regsub!G:G, base_regsub!A:A, cesta_idrgp!$A156, base_regsub!D:D, cesta_idrgp!$C156) -> 216731.53
A157: =_xlfn.CONCAT(B157, ".", C157) -> 2022.5426 | B157: 2022 | C157: 5426 | D157: =VLOOKUP(A157, base_regsub!A:E, 5, FALSE) -> #N/A | E157: =SUMIFS(base_regsub!G:G, base_regsub!A:A, cesta_idrgp!$A157, base_regsub!D:D, cesta_idrgp!$C157) -> 0
A158: =_xlfn.CONCAT(B158, ".", C158) -> 2022.5474 | B158: 2022 | C158: 5474 | D158: =VLOOKUP(A158, base_regsub!A:E, 5, FALSE) -> #N/A | E158: =SUMIFS(base_regsub!G:G, base_regsub!A:A, cesta_idrgp!$A158, base_regsub!D:D, cesta_idrgp!$C158) -> 0
A159: =_xlfn.CONCAT(B159, ".", C159) -> 2022.5601 | B159: 2022 | C159: 5601 | D159: =VLOOKUP(A159, base_regsub!A:E, 5, FALSE) -> #N/A | E159: =SUMIFS(base_regsub!G:G, base_regsub!A:A, cesta_idrgp!$A159, base_regsub!D:D, cesta_idrgp!$C159) -> 0
A160: =_xlfn.CONCAT(B160, ".", C160) -> 2022.5602 | B160: 2022 | C160: 5602 | D160: =VLOOKUP(A160, base_regsub!A:E, 5, FALSE) -> #N/A | E160: =SUMIFS(base_regsub!G:G, base_regsub!A:A, cesta_idrgp!$A160, base_regsub!D:D, cesta_idrgp!$C160) -> 0
A161: =_xlfn.CONCAT(B161, ".", C161) -> 2022.5959 | B161: 2022 | C161: 5959 | D161: =VLOOKUP(A161, base_regsub!A:E, 5, FALSE) -> #N/A | E161: =SUMIFS(base_regsub!G:G, base_regsub!A:A, cesta_idrgp!$A161, base_regsub!D:D, cesta_idrgp!$C161) -> 0
A162: =_xlfn.CONCAT(B162, ".", C162) -> 2022.5960 | B162: 2022 | C162: 5960 | D162: =VLOOKUP(A162, base_regsub!A:E, 5, FALSE) -> Ampliação, Reforma e Requalificação de Equipamentos Culturais | E162: =SUMIFS(base_regsub!G:G, base_regsub!A:A, cesta_idrgp!$A162, base_regsub!D:D, cesta_idrgp!$C162) -> 4115433.7
A163: =_xlfn.CONCAT(B163, ".", C163) -> 2022.6151 | B163: 2022 | C163: 6151 | D163: =VLOOKUP(A163, base_regsub!A:E, 5, FALSE) -> #N/A | E163: =SUMIFS(base_regsub!G:G, base_regsub!A:A, cesta_idrgp!$A163, base_regsub!D:D, cesta_idrgp!$C163) -> 0
A164: =_xlfn.CONCAT(B164, ".", C164) -> 2022.6160 | B164: 2022 | C164: 6160 | D164: =VLOOKUP(A164, base_regsub!A:E, 5, FALSE) -> #N/A | E164: =SUMIFS(base_regsub!G:G, base_regsub!A:A, cesta_idrgp!$A164, base_regsub!D:D, cesta_idrgp!$C164) -> 0
A165: =_xlfn.CONCAT(B165, ".", C165) -> 2022.6163 | B165: 2022 | C165: 6163 | D165: =VLOOKUP(A165, base_regsub!A:E, 5, FALSE) -> #N/A | E165: =SUMIFS(base_regsub!G:G, base_regsub!A:A, cesta_idrgp!$A165, base_regsub!D:D, cesta_idrgp!$C165) -> 0
A166: =_xlfn.CONCAT(B166, ".", C166) -> 2022.6166 | B166: 2022 | C166: 6166 | D166: =VLOOKUP(A166, base_regsub!A:E, 5, FALSE) -> Programa de Garantia de Renda Familiar Mínima | E166: =SUMIFS(base_regsub!G:G, base_regsub!A:A, cesta_idrgp!$A166, base_regsub!D:D, cesta_idrgp!$C166) -> 7491383.6
...

Sheet n_acoes_ano
A1: regionalizado_sub | B1: (Vários itens)
A3: ano | B3: Contagem de código_proj_ativ
A4: 2022 | B4: 29
A5: 2023 | B5: 51
A6: 2024 | B6: 42
A7: 2025 | B7: 52
A8: Total Geral | B8: 174
